#VRML_SIM R2020b utf8
WorldInfo {
  coordinateSystem "NUE"
}
Viewpoint {
  orientation -0.010272065402168637 0.978977798025452 0.2037080156636226 2.937224707851601
  position 0.1934903532966435 0.5691138201498999 -1.237744607582814
}
TexturedBackground {
}
TexturedBackgroundLight {
}
RectangleArena {
  translation 0 0.01 0
  floorSize 20 20
  floorTileSize 20 20
}
Robot {
  translation -2.0481104146441342e-12 0.07065506857433701 1.6107865969567077e-08
  rotation 0.9999999981370684 6.103616518057084e-05 6.704786060608826e-07 9.645579796124481e-09
  children [
    Solid {
      children [
        Gyro {
        }
        HingeJoint {
          jointParameters HingeJointParameters {
            position 3.3299571501293115e-11
            axis 0 0 1
            anchor 0.167 0 -0.232
          }
          device [
            RotationalMotor {
              name "PWM[0]"
              maxVelocity 87.4102
            }
          ]
          endPoint Solid {
            translation 0.167 0 -0.232
            rotation 1 3.2688069148542187e-10 3.268794907878028e-10 1.5708
            children [
              Shape {
                appearance PBRAppearance {
                  metalness 0.5
                }
                geometry DEF Wheel Cylinder {
                  height 0.0125
                  radius 0.0635
                }
              }
            ]
            name "FL"
            boundingObject USE Wheel
            physics Physics {
            }
            linearVelocity 6.295786258926262e-12 3.299086424547152e-07 3.5650193433295904e-13
            angularVelocity -4.6692875283264295e-14 -6.963782187685132e-12 -1.019291983144997e-10
          }
        }
        HingeJoint {
          jointParameters HingeJointParameters {
            position 3.3292730302553466e-11
            axis 0 0 1
            anchor 0 0 -0.232
          }
          device [
            RotationalMotor {
              name "PWM[2]"
              maxVelocity 87.4102
            }
          ]
          endPoint Solid {
            translation 0 0 -0.232
            rotation 1 3.4347633096187237e-10 3.4347506930517795e-10 1.5708
            children [
              Shape {
                appearance PBRAppearance {
                  metalness 0.5
                }
                geometry USE Wheel
              }
            ]
            name "ML"
            boundingObject USE Wheel
            physics Physics {
            }
            linearVelocity 6.296261180112445e-12 3.299084751689915e-07 -5.515781448823897e-15
            angularVelocity -7.965255201085055e-14 -6.963782188295819e-12 -1.0194273771192894e-10
          }
        }
        HingeJoint {
          jointParameters HingeJointParameters {
            position 3.329191698667937e-11
            axis 0 0 1
            anchor -0.167 0 -0.232
          }
          device [
            PositionSensor {
              name "Encoder[0,1]"
            }
            RotationalMotor {
              name "PWM[4]"
              maxVelocity 87.4102
            }
          ]
          endPoint Solid {
            translation -0.167 0 -0.232
            rotation 1 3.1015149349990377e-10 3.101503542519476e-10 1.5708
            children [
              Shape {
                appearance PBRAppearance {
                  metalness 0.5
                }
                geometry USE Wheel
              }
            ]
            name "BL"
            boundingObject USE Wheel
            physics Physics {
            }
            linearVelocity 6.295338772556169e-12 3.299083042935746e-07 -3.6842505210927103e-13
            angularVelocity -1.3458534655689051e-13 -6.963782186216358e-12 -1.0192545700904554e-10
          }
        }
        HingeJoint {
          jointParameters HingeJointParameters {
            position -4.671292969962744e-14
            axis 0 0 1
            anchor 0.167 0 0.232
          }
          device [
            RotationalMotor {
              name "PWM[1]"
              maxVelocity 87.4102
            }
          ]
          endPoint Solid {
            translation 0.167 0 0.232
            rotation 1 2.6873027253514517e-11 2.6872928543554963e-11 1.5708
            children [
              Shape {
                appearance PBRAppearance {
                  metalness 0.5
                }
                geometry USE Wheel
              }
            ]
            name "FR"
            boundingObject USE Wheel
            physics Physics {
            }
            linearVelocity 5.287436546350439e-12 3.2990924267291063e-07 3.5689965297083323e-13
            angularVelocity -4.119959582899148e-14 -6.963782705773473e-12 -1.0177948778187909e-10
          }
        }
        HingeJoint {
          jointParameters HingeJointParameters {
            position 3.329169013073424e-11
            axis 0 0 1
            anchor 0 0 0.232
          }
          device [
            RotationalMotor {
              name "PWM[3]"
              maxVelocity 87.4102
            }
          ]
          endPoint Solid {
            translation 0 0 0.232
            rotation 1 3.7679483547862193e-10 3.767934514364517e-10 1.5708
            children [
              Shape {
                appearance PBRAppearance {
                  metalness 0.5
                }
                geometry USE Wheel
              }
            ]
            name "MR"
            boundingObject USE Wheel
            physics Physics {
            }
            linearVelocity 5.2884872324460305e-12 3.2990907538724594e-07 -6.333016095183543e-15
            angularVelocity -1.0437230955662983e-13 -6.963782706127472e-12 -1.0180517808579545e-10
          }
        }
        HingeJoint {
          jointParameters HingeJointParameters {
            position 7.403170605269745e-15
            axis 0 0 1
            anchor -0.167 0 0.232
          }
          device [
            PositionSensor {
              name "Encoder[2,3]"
            }
            RotationalMotor {
              name "PWM[5]"
              maxVelocity 87.4102
            }
          ]
          endPoint Solid {
            translation -0.167 0 0.232
            rotation 1 6.338329713605687e-12 6.338306431663402e-12 1.5708
            children [
              Shape {
                appearance PBRAppearance {
                  metalness 0.5
                }
                geometry USE Wheel
              }
            ]
            name "BR"
            boundingObject USE Wheel
            physics Physics {
            }
            linearVelocity -3.711329238730592e-12 3.2990891025544045e-07 -3.691382809514484e-13
            angularVelocity -1.5381182481076108e-13 -6.963782654040481e-12 1.0360383913155832e-10
          }
        }
        Shape {
          appearance PBRAppearance {
          }
          geometry DEF Base Box {
            size 0.46101 0.05 0.45085
          }
        }
      ]
      boundingObject USE Base
      physics Physics {
      }
    }
    Pen {
      translation 0 0.001 0
      inkColor 1 0 0
      inkDensity 1
      leadSize 0.1
    }
  ]
  boundingObject USE Base
  physics Physics {
    density -1
    mass 10
  }
  controller "DeepBlueSim"
  linearVelocity 4.286470833409485e-12 -2.8998063045568044e-10 -5.8798639818568414e-15
  angularVelocity -1.4752595942314454e-13 -6.964388809308194e-12 1.0085673068758854e-12
}
